Workbook

Sheet INVOICE
A1: INVOICE
G5: インボイス作成日（Date): 5/12/2025
A8: 依頼住 (Shipper Address) | G8: Invoice No MASUDA VN-JP 019/25
A10: MASUDA VINYL VIETNAM CO.,LTD
A11: LOT NO1 DONG VANG DINH TRAM INDUSTRIAL ZONE | G11: (原産国) Country of Origin | I11: (仕向先国名) Country of Destination
A12: NENH WARD BAC NINH PROVINCE
A13: TEL : 0204 3662 777 | G13: VIETNAM | I13: JAPAN
A14: FAX : 0204 3662 825 | G14: 支払条件 (Terms of Payment)
G15: 20日締め翌月末支払 (Invoice will be closed on 20th every month and payment at end of the following month)
A16: 荷受人(Consigneer)
A19: MASUDA VINYL CO.,LTD
A20: 390ROKUGAIKECYOU KITAKU | G20: 備考 (Remark):
A21: NAGOYA CITY AICHI JAPAN
A22: TEL : 052-901-9373 | G22: P | H22: 有償（Commerical Value)
A23: FAX : 052-901-6943 | H23: 無償（No Commerical Value)
A25: Delivery to (着地) | F25: CIF | H25: 贈物（Gift)
H26: 商品見本（ Sample, No Commercial Value )
H27: その他（Other)
A30: ラベル内容 (Marks & Nos.) | B30: 内容品の記載 (Description) | D30: 注文書No PO No | E30: 単位 （Unit） | F30: 数量 （Quantity) | G30: 単価 （Unit Price） | I30: 合計 （Total Amount)
A33: 1/13 | B33: TABLE EDGE MG23 | E33: =VLOOKUP(B33,データ!$B$3:$L$85,11,FALSE) -> m | F33: 4000 | G33: =VLOOKUP(B33,データ!$B$3:$C$85,2,FALSE) -> 0.61 | I33: =G33*F33 -> 2440
A34: 2/13 | B34: PUROTEKUTA 55788-16110 | E34: =VLOOKUP(B34,データ!$B$3:$L$85,11,FALSE) -> pcs | F34: 11000 | G34: =VLOOKUP(B34,データ!$B$3:$C$85,2,FALSE) -> 0.223 | I34: =G34*F34 -> 2453
A35: 3/13 | B35: PUROTEKUTA 55788-52350 | E35: =VLOOKUP(B35,データ!$B$3:$L$85,11,FALSE) -> pcs | F35: 6000 | G35: =VLOOKUP(B35,データ!$B$3:$C$85,2,FALSE) -> 0.213 | I35: =G35*F35 -> 1278
B36: PUROTEKUTA 55788-52360 | E36: =VLOOKUP(B36,データ!$B$3:$L$85,11,FALSE) -> pcs | F36: 5000 | G36: =VLOOKUP(B36,データ!$B$3:$C$85,2,FALSE) -> 0.223 | I36: =G36*F36 -> 1115
A37: 4/13 | B37: PUROTEKUTA 2A4P1-022G | E37: =VLOOKUP(B37,データ!$B$3:$L$85,11,FALSE) -> pcs | F37: 11000 | G37: =VLOOKUP(B37,データ!$B$3:$C$85,2,FALSE) -> 0.235 | I37: =G37*F37 -> 2585
B38: PUROTEKUTA 55788-K0060 | E38: =VLOOKUP(B38,データ!$B$3:$L$85,11,FALSE) -> pcs | F38: 5500 | G38: =VLOOKUP(B38,データ!$B$3:$C$85,2,FALSE) -> 0.224 | I38: =G38*F38 -> 1232
A39: 5/13 | B39: PUROTEKUTA 55788-48090 | E39: =VLOOKUP(B39,データ!$B$3:$L$85,11,FALSE) -> pcs | F39: 9000 | G39: =VLOOKUP(B39,データ!$B$3:$C$85,2,FALSE) -> 0.251 | I39: =G39*F39 -> 2259
B40: PUROTEKUTA 55788-K0060 | E40: =VLOOKUP(B40,データ!$B$3:$L$85,11,FALSE) -> pcs | F40: 5500 | G40: =VLOOKUP(B40,データ!$B$3:$C$85,2,FALSE) -> 0.224 | I40: =G40*F40 -> 1232
A41: 6/13 | B41: PUROTEKUTA 55788-K0060 | E41: =VLOOKUP(B41,データ!$B$3:$L$85,11,FALSE) -> pcs | F41: 13500 | G41: =VLOOKUP(B41,データ!$B$3:$C$85,2,FALSE) -> 0.224 | I41: =G41*F41 -> 3024
A42: 7/13 | B42: PUROTEKUTA 55788-60110 | E42: =VLOOKUP(B42,データ!$B$3:$L$85,11,FALSE) -> pcs | F42: 13000 | G42: =VLOOKUP(B42,データ!$B$3:$C$85,2,FALSE) -> 0.223 | I42: =G42*F42 -> 2899
B43: RAB0938-V+H450 - N | E43: =VLOOKUP(B43,データ!$B$3:$DH$185,11,FALSE) -> pcs | F43: 7 | G43: =VLOOKUP(B43,データ!$B$3:$C$185,2,FALSE) -> 2.91 | I43: =G43*F43 -> 20.37
A44: 8/13-12/13 | B44: MASK 42811 | E44: =VLOOKUP(B44,データ!$B$3:$L$85,11,FALSE) -> bag | F44: 12000 | G44: =VLOOKUP(B44,データ!$B$3:$C$85,2,FALSE) -> 0.2 | I44: =G44*F44 -> 2400
A45: 13/13 | B45: TABLE EDGE MI3 156 | E45: =VLOOKUP(B45,データ!$B$3:$L$85,11,FALSE) -> pcs | F45: 240 | G45: =VLOOKUP(B45,データ!$B$3:$C$85,2,FALSE) -> 2.875 | I45: =G45*F45 -> 690
A46: 合計 （Total) | I46: =SUM(I33:K45) -> 23627.37
A49: 原産国 (Country of Origin) : VIETNAM | G49: 署名（ Singnature )
A50: CIF TO NAGOYA PORT

Sheet PACKING LIST
A1: PACKING LIST
H5: =INVOICE!G5 -> インボイス作成日（Date): 5/12/2025
A8: 依頼住 (Shipper Address) | H8: =INVOICE!G8 -> Invoice No MASUDA VN-JP 019/25
A10: MASUDA VINYL VIETNAM CO.,LTD
A11: LOT NO1 DONG VANG DINH TRAM INDUSTRIAL ZONE | H11: (原産国) Country of Origin | J11: (仕向先国名) Country of Destination
A12: NENH WARD BAC NINH PROVINCE
A13: TEL : 0204 3662 777 | H13: VIETNAM | J13: JAPAN
A14: FAX : 0204 3662 825 | H14: 支払条件 (Terms of Payment)
H15: 20日締め翌月末支払 (Invoice will be closed on 20th every month and payment at end of the following month)
A17: 荷受人(Consigneer)
A20: MASUDA VINYL CO.,LTD | H20: 備考 (Remark):
A21: 390ROKUGAIKECYOU KITAKU
A22: NAGOYA CITY AICHI JAPAN | H22: P | I22: 有償（Commerical Value)
A23: TEL : 052-901-9373 | I23: 無償（No Commerical Value)
A24: FAX : 052-901-6943
I25: 贈物（Gift)
A26: Delivery to (着地) | G26: CIF | I26: 商品見本（ Sample, No Commercial Value )
I27: その他（Other)
A31: ラベル内容 (Marks & Nos.) | B31: 内容品の記載 (Description) | D31: 注文書No PO No | E31: 単位 （Unit） | F31: 数量 （Quantity) | G31: 梱包 （Packing） | I31: 箱数 ( Number of Boxs) | J31: パレット数 ( Number of Pallets) | K31: 総重量 (Gross weight)
A35: 1/13 | B35: =INVOICE!B33 -> TABLE EDGE MG23 | E35: =INVOICE!E33 -> m | F35: =INVOICE!F33 -> 4000 | G35: =VLOOKUP(B35,データ!$B$3:$E$85,4,FALSE) -> 50 | I35: =ROUNDUP(F35/G35,0) -> 80 | J35: 1 | K35: =ROUND(N35+P35+20,2) -> 20
A36: 2/13 | B36: =INVOICE!B34 -> PUROTEKUTA 55788-16110 | E36: =INVOICE!E34 -> pcs | F36: =INVOICE!F34 -> 11000 | G36: =VLOOKUP(B36,データ!$B$3:$E$85,4,FALSE) -> 500 | I36: =ROUNDUP(F36/G36,0) -> 22 | J36: 1 | K36: =ROUND(N36+P36,2)+10 -> 10
A37: 3/13 | B37: =INVOICE!B35 -> PUROTEKUTA 55788-52350 | E37: =INVOICE!E35 -> pcs | F37: =INVOICE!F35 -> 6000 | G37: =VLOOKUP(B37,データ!$B$3:$E$85,4,FALSE) -> 500 | I37: =ROUNDUP(F37/G37,0) -> 12 | J37: 1 | K37: =ROUND(N37+P37,2)+5 -> 5
B38: =INVOICE!B36 -> PUROTEKUTA 55788-52360 | E38: =INVOICE!E36 -> pcs | F38: =INVOICE!F36 -> 5000 | G38: =VLOOKUP(B38,データ!$B$3:$E$85,4,FALSE) -> 500 | I38: =ROUNDUP(F38/G38,0) -> 10 | K38: =ROUND(N38+P38,2)+5 -> 5
A39: 4/13 | B39: =INVOICE!B37 -> PUROTEKUTA 2A4P1-022G | E39: =INVOICE!E37 -> pcs | F39: =INVOICE!F37 -> 11000 | G39: =VLOOKUP(B39,データ!$B$3:$E$85,4,FALSE) -> 500 | I39: =ROUNDUP(F39/G39,0) -> 22 | J39: 1 | K39: =ROUND(N39+P39,2)+10 -> 10
B40: =INVOICE!B38 -> PUROTEKUTA 55788-K0060 | E40: =INVOICE!E38 -> pcs | F40: =INVOICE!F38 -> 5500 | G40: =VLOOKUP(B40,データ!$B$3:$E$85,4,FALSE) -> 500 | I40: =ROUNDUP(F40/G40,0) -> 11 | K40: =ROUND(N40+P40,2)+10 -> 10
A41: 5/13 | B41: =INVOICE!B39 -> PUROTEKUTA 55788-48090 | E41: =INVOICE!E39 -> pcs | F41: =INVOICE!F39 -> 9000 | G41: =VLOOKUP(B41,データ!$B$3:$E$85,4,FALSE) -> 500 | I41: =ROUNDUP(F41/G41,0) -> 18 | J41: 1 | K41: =ROUND(N41+P41,2)+10 -> 10
B42: =INVOICE!B40 -> PUROTEKUTA 55788-K0060 | E42: =INVOICE!E40 -> pcs | F42: =INVOICE!F40 -> 5500 | G42: =VLOOKUP(B42,データ!$B$3:$E$85,4,FALSE) -> 500 | I42: =ROUNDUP(F42/G42,0) -> 11 | K42: =ROUND(N42+P42,2)+10 -> 10
A43: 6/13 | B43: =INVOICE!B41 -> PUROTEKUTA 55788-K0060 | E43: =INVOICE!E41 -> pcs | F43: =INVOICE!F41 -> 13500 | G43: =VLOOKUP(B43,データ!$B$3:$E$85,4,FALSE) -> 500 | I43: =ROUNDUP(F43/G43,0) -> 27 | J43: 1 | K43: =ROUND(N43+P43,2)+20 -> 20
A44: 7/13 | B44: =INVOICE!B42 -> PUROTEKUTA 55788-60110 | E44: =INVOICE!E42 -> pcs | F44: =INVOICE!F42 -> 13000 | G44: =VLOOKUP(B44,データ!$B$3:$E$85,4,FALSE) -> 500 | I44: =ROUNDUP(F44/G44,0) -> 26 | J44: 1 | K44: =ROUND(N44+P44,2)+20 -> 20
B45: =INVOICE!B43 -> RAB0938-V+H450 - N | E45: =INVOICE!E43 -> pcs | F45: =INVOICE!F43 -> 7 | G45: 7 | I45: =ROUNDUP(F45/G45,0) -> 1 | K45: =ROUND(N45+P45,2) -> 0
A46: 8/13-12/13 | B46: =INVOICE!B44 -> MASK 42811 | E46: =INVOICE!E44 -> bag | F46: =INVOICE!F44 -> 12000 | G46: =VLOOKUP(B46,データ!$B$3:$E$85,4,FALSE) -> 120 | I46: =ROUNDUP(F46/G46,0) -> 100 | J46: 5 | K46: =ROUND(N46+P46,2)+100 -> 100
A47: 13/13 | B47: =INVOICE!B45 -> TABLE EDGE MI3 156 | E47: =INVOICE!E45 -> pcs | F47: =INVOICE!F45 -> 240 | G47: =VLOOKUP(B47,データ!$B$3:$E$85,4,FALSE) -> 30 | I47: =ROUNDUP(F47/G47,0) -> 8 | J47: 1 | K47: =ROUND(N47+P47,2)+20 -> 20
A49: 合計 （Total) | F49: =SUMIF(E35:E48,L42,F35:F48) -> 0 | I49: =SUMIF(E35:E48,L42,I35:I48)+SUMIF(E35:E48,L44,I35:I48) -> 0 | J49: =SUM(J35:J48) -> 13 | K49: =SUM(K35:K48) -> 240
F51: =SUMIF(E35:E48,L43,F35:F48) -> 0 | I51: =SUMIF(E35:E48,L43,I35:I48) -> 0
F52: =SUMIF(E35:E48,L44,F35:F48) -> 0
A53: =INVOICE!A50 -> CIF TO NAGOYA PORT
A54: 郵便物の個数 ( Number of pieces, m) : | D54: =F49 -> 0 | E54: =F51 -> 0 | F54: =F52 -> 0 | I54: 署名（ Singnature )
A55: 総重量（Gross weight) Kg : | D55: =K49 -> 240 | E55: =J49 -> 13
A56: 原産国（Country of Origin) :VIETNAM | D56: =1.1*1.5*1.1*6+1.1*1.1*1.4+1.1*1.2*1.8*5+1.1*1.1*1 -> 25.674
A57: 輸送方法 ( Shipped per) : SEA

Sheet IV tong
A1: INVOICE
F5: =INVOICE!G5 -> インボイス作成日（Date): 5/12/2025
A8: 依頼住 (Shipper Address) | F8: =INVOICE!G8 -> Invoice No MASUDA VN-JP 019/25
A10: MASUDA VINYL VIETNAM CO.,LTD
A11: LOT NO1 DONG VANG DINH TRAM INDUSTRIAL ZONE | F11: (原産国) Country of Origin | H11: (仕向先国名) Country of Destination
A12: NENH TOWN VIET YEN DISTRICT BAC GIANG PROVINCE
A13: TEL : 0204 3662 777 | F13: VIETNAM | H13: JAPAN
A14: FAX : 0204 3662 825 | F14: 支払条件 (Terms of Payment)
F15: 20日締め翌月末支払 (Invoice will be closed on 20th every month and payment at end of the following month)
A16: 荷受人(Consigneer)
A19: MASUDA VINYL CO.,LTD
A20: 390ROKUGAIKECYOU KITAKU | F20: 備考 (Remark):
A21: NAGOYA CITY AICHI JAPAN
A22: TEL : 052-901-9373 | F22: P | G22: 有償（Commerical Value)
A23: FAX : 052-901-6943 | G23: 無償（No Commerical Value)
A25: From (発地国) | E25: Via (経由国) | G25: 贈物（Gift)
A26: BACGIANG VIETNAM | E26: CIF | G26: 商品見本（ Sample, No Commercial Value )
A27: To (着地国) | G27: その他（Other)
A28: NAGOYA JAPAN
A30: ラベル内容 (Marks & Nos.) | B30: 内容品の記載 (Description) | D30: 単位 （Unit） | E30: 数量 （Quantity) | F30: 単価 （Unit Price） | H30: 合計 （Total Amount)
K33: Mã HS code | L33: ĐVT 2 | M33: trọng lượng | N33: SL2 | O33: IV | P33: SO SÁNH
A34: 1 | B34: PUROTEKUTA 55788-60110 | D34: =VLOOKUP(B34,データ!$B$3:$L$85,11,FALSE) -> pcs | E34: 13000 | F34: =VLOOKUP(B34,データ!$B$3:$C$85,2,FALSE) -> 0.223 | H34: =F34*E34 -> 2899 | K34: =_xlfn.IFNA(VLOOKUP(B34,データ!$B$3:$O$137,12,0),"") -> 39169092 | L34: =_xlfn.IFNA(VLOOKUP(B34,データ!$B$3:$O$137,13,0),"") -> Kg | M34: =_xlfn.IFNA(VLOOKUP(B34,データ!$B$3:$D$127,3,FALSE),"") -> 25 | N34: =IF(L34="kg",M34*E34/1000,AND(IF(L34="PCE",E34))) -> 325 | O34: =SUMIF(INVOICE!$B$33:$C$45,B34,INVOICE!$F$33:$F$45) -> 13000 | P34: =+E34-O34 -> 0
A35: =A34+1 -> 2 | B35: PUROTEKUTA 55788-16110 | D35: =VLOOKUP(B35,データ!$B$3:$L$85,11,FALSE) -> pcs | E35: 11000 | F35: =VLOOKUP(B35,データ!$B$3:$C$85,2,FALSE) -> 0.223 | H35: =F35*E35 -> 2453 | K35: =_xlfn.IFNA(VLOOKUP(B35,データ!$B$3:$O$137,12,0),"") -> 39169092 | L35: =_xlfn.IFNA(VLOOKUP(B35,データ!$B$3:$O$137,13,0),"") -> Kg | M35: =_xlfn.IFNA(VLOOKUP(B35,データ!$B$3:$D$127,3,FALSE),"") -> 25 | N35: =IF(L35="kg",M35*E35/1000,AND(IF(L35="PCE",E35))) -> 275 | O35: =SUMIF(INVOICE!$B$33:$C$45,B35,INVOICE!$F$33:$F$45) -> 11000 | P35: =+E35-O35 -> 0
A36: =A35+1 -> 3 | B36: PUROTEKUTA 55788-K0060 | D36: =VLOOKUP(B36,データ!$B$3:$L$85,11,FALSE) -> pcs | E36: 24500 | F36: =VLOOKUP(B36,データ!$B$3:$C$85,2,FALSE) -> 0.224 | H36: =F36*E36 -> 5488 | K36: =_xlfn.IFNA(VLOOKUP(B36,データ!$B$3:$O$137,12,0),"") -> 39169092 | L36: =_xlfn.IFNA(VLOOKUP(B36,データ!$B$3:$O$137,13,0),"") -> Kg | M36: =_xlfn.IFNA(VLOOKUP(B36,データ!$B$3:$D$127,3,FALSE),"") -> 23 | N36: =IF(L36="kg",M36*E36/1000,AND(IF(L36="PCE",E36))) -> 563.5 | O36: =SUMIF(INVOICE!$B$33:$C$45,B36,INVOICE!$F$33:$F$45) -> 24500 | P36: =+E36-O36 -> 0
A37: =A36+1 -> 4 | B37: PUROTEKUTA 2A4P1-022G | D37: =VLOOKUP(B37,データ!$B$3:$L$85,11,FALSE) -> pcs | E37: 11000 | F37: =VLOOKUP(B37,データ!$B$3:$C$85,2,FALSE) -> 0.235 | H37: =F37*E37 -> 2585 | K37: =_xlfn.IFNA(VLOOKUP(B37,データ!$B$3:$O$137,12,0),"") -> 39169092 | L37: =_xlfn.IFNA(VLOOKUP(B37,データ!$B$3:$O$137,13,0),"") -> Kg | M37: =_xlfn.IFNA(VLOOKUP(B37,データ!$B$3:$D$127,3,FALSE),"") -> 23.5 | N37: =IF(L37="kg",M37*E37/1000,AND(IF(L37="PCE",E37))) -> 258.5 | O37: =SUMIF(INVOICE!$B$33:$C$45,B37,INVOICE!$F$33:$F$45) -> 11000 | P37: =+E37-O37 -> 0
A38: =A37+1 -> 5 | B38: PUROTEKUTA 55788-48090 | D38: =VLOOKUP(B38,データ!$B$3:$L$85,11,FALSE) -> pcs | E38: 9000 | F38: =VLOOKUP(B38,データ!$B$3:$C$85,2,FALSE) -> 0.251 | H38: =F38*E38 -> 2259 | K38: =_xlfn.IFNA(VLOOKUP(B38,データ!$B$3:$O$137,12,0),"") -> 39169092 | L38: =_xlfn.IFNA(VLOOKUP(B38,データ!$B$3:$O$137,13,0),"") -> Kg | M38: =_xlfn.IFNA(VLOOKUP(B38,データ!$B$3:$D$127,3,FALSE),"") -> 25 | N38: =IF(L38="kg",M38*E38/1000,AND(IF(L38="PCE",E38))) -> 225 | O38: =SUMIF(INVOICE!$B$33:$C$45,B38,INVOICE!$F$33:$F$45) -> 9000 | P38: =+E38-O38 -> 0
A39: =A38+1 -> 6 | B39: PUROTEKUTA 55788-52360 | D39: =VLOOKUP(B39,データ!$B$3:$L$85,11,FALSE) -> pcs | E39: 5000 | F39: =VLOOKUP(B39,データ!$B$3:$C$85,2,FALSE) -> 0.223 | H39: =F39*E39 -> 1115 | K39: =_xlfn.IFNA(VLOOKUP(B39,データ!$B$3:$O$137,12,0),"") -> 39169092 | L39: =_xlfn.IFNA(VLOOKUP(B39,データ!$B$3:$O$137,13,0),"") -> Kg | M39: =_xlfn.IFNA(VLOOKUP(B39,データ!$B$3:$D$127,3,FALSE),"") -> 25 | N39: =IF(L39="kg",M39*E39/1000,AND(IF(L39="PCE",E39))) -> 125 | O39: =SUMIF(INVOICE!$B$33:$C$45,B40,INVOICE!$F$33:$F$45) -> 6000 | P39: =+E40-O39 -> 0
A40: =A39+1 -> 7 | B40: PUROTEKUTA 55788-52350 | D40: =VLOOKUP(B40,データ!$B$3:$L$85,11,FALSE) -> pcs | E40: 6000 | F40: =VLOOKUP(B40,データ!$B$3:$C$85,2,FALSE) -> 0.213 | H40: =F40*E40 -> 1278 | K40: =_xlfn.IFNA(VLOOKUP(B40,データ!$B$3:$O$137,12,0),"") -> 39169092 | L40: =_xlfn.IFNA(VLOOKUP(B40,データ!$B$3:$O$137,13,0),"") -> Kg | M40: =_xlfn.IFNA(VLOOKUP(B40,データ!$B$3:$D$127,3,FALSE),"") -> 23.5 | N40: =IF(L40="kg",M40*E40/1000,AND(IF(L40="PCE",E40))) -> 141 | O40: =SUMIF(INVOICE!$B$33:$C$45,#REF!,INVOICE!$F$33:$F$45) -> 0 | P40: =+E41-O40 -> 4000
A41: =A40+1 -> 8 | B41: TABLE EDGE MG23 | D41: =VLOOKUP(B41,データ!$B$3:$L$85,11,FALSE) -> m | E41: 4000 | F41: =VLOOKUP(B41,データ!$B$3:$C$85,2,FALSE) -> 0.61 | H41: =F41*E41 -> 2440 | K41: =_xlfn.IFNA(VLOOKUP(B41,データ!$B$3:$O$137,12,0),"") -> 39169092 | L41: =_xlfn.IFNA(VLOOKUP(B41,データ!$B$3:$O$137,13,0),"") -> Kg | M41: =_xlfn.IFNA(VLOOKUP(B41,データ!$B$3:$D$127,3,FALSE),"") -> 78 | N41: =IF(L41="kg",M41*E41/1000,AND(IF(L41="PCE",E41))) -> 312 | O41: =SUMIF(INVOICE!$B$33:$C$45,#REF!,INVOICE!$F$33:$F$45) -> 0 | P41: =+E42-O41 -> 240
A42: =A41+1 -> 9 | B42: TABLE EDGE MI3 156 | D42: =VLOOKUP(B42,データ!$B$3:$L$85,11,FALSE) -> pcs | E42: 240 | F42: =VLOOKUP(B42,データ!$B$3:$C$85,2,FALSE) -> 2.875 | H42: =F42*E42 -> 690 | K42: =_xlfn.IFNA(VLOOKUP(B42,データ!$B$3:$O$137,12,0),"") -> 39169092 | L42: =_xlfn.IFNA(VLOOKUP(B42,データ!$B$3:$O$137,13,0),"") -> Kg | M42: =_xlfn.IFNA(VLOOKUP(B42,データ!$B$3:$D$127,3,FALSE),"") -> 691.38 | N42: =IF(L42="kg",M42*E42/1000,AND(IF(L42="PCE",E42))) -> 165.9312 | O42: =SUMIF(INVOICE!$B$33:$C$45,B41,INVOICE!$F$33:$F$45) -> 4000 | P42: =+E43-O42 -> 8000
A43: =A42+1 -> 10 | B43: MASK 42811 | D43: =VLOOKUP(B43,データ!$B$3:$L$85,11,FALSE) -> bag | E43: 12000 | F43: =VLOOKUP(B43,データ!$B$3:$C$85,2,FALSE) -> 0.2 | H43: =F43*E43 -> 2400 | K43: =_xlfn.IFNA(VLOOKUP(B43,データ!$B$3:$O$137,12,0),"") -> 0 | L43: =_xlfn.IFNA(VLOOKUP(B43,データ!$B$3:$O$137,13,0),"") -> 0 | M43: =_xlfn.IFNA(VLOOKUP(B43,データ!$B$3:$D$127,3,FALSE),"") -> 83.3 | N43: =IF(L43="kg",M43*E43/1000,AND(IF(L43="PCE",E43))) -> FALSE | O43: =SUMIF(INVOICE!$B$33:$C$45,B42,INVOICE!$F$33:$F$45) -> 240 | P43: =+E44-O43 -> -233
A44: =A43+1 -> 11 | B44: RAB0938-V+H450 - N | D44: =VLOOKUP(B44,データ!$B$3:$L$185,11,FALSE) -> pcs | E44: 7 | F44: =VLOOKUP(B44,データ!$B$3:$C$185,2,FALSE) -> 2.91 | H44: =F44*E44 -> 20.37 | K44: =_xlfn.IFNA(VLOOKUP(B44,データ!$B$3:$O$137,12,0),"") -> 39169092 | L44: =_xlfn.IFNA(VLOOKUP(B44,データ!$B$3:$O$137,13,0),"") -> Kg | M44: =_xlfn.IFNA(VLOOKUP(B44,データ!$B$3:$D$127,3,FALSE),"") -> 435.04478 | N44: =IF(L44="kg",M44*E44/1000,AND(IF(L44="PCE",E44))) -> 3.0453134 | O44: =SUMIF(INVOICE!$B$33:$C$45,B43,INVOICE!$F$33:$F$45) -> 12000 | P44: =+E45-O44 -> -12000
A45: =A44+1 -> 12 | K45: =_xlfn.IFNA(VLOOKUP(B45,データ!$B$3:$O$137,12,0),"") | L45: =_xlfn.IFNA(VLOOKUP(B45,データ!$B$3:$O$137,13,0),"") | M45: =_xlfn.IFNA(VLOOKUP(B45,データ!$B$3:$D$127,3,FALSE),"") | N45: =IF(L45="kg",M45*E45/1000,AND(IF(L45="PCE",E45))) -> FALSE | O45: =SUMIF(INVOICE!$B$33:$C$45,B44,INVOICE!$F$33:$F$45) -> 7 | P45: =+E46-O45 -> -7
A46: =A45+1 -> 13 | K46: =_xlfn.IFNA(VLOOKUP(B46,データ!$B$3:$O$137,12,0),"") | L46: =_xlfn.IFNA(VLOOKUP(B46,データ!$B$3:$O$137,13,0),"") | M46: =_xlfn.IFNA(VLOOKUP(B46,データ!$B$3:$D$127,3,FALSE),"") | N46: =IF(L46="kg",M46*E46/1000,AND(IF(L46="PCE",E46))) -> FALSE | O46: =SUMIF(INVOICE!$B$33:$C$45,B45,INVOICE!$F$33:$F$45) -> 0 | P46: =+E47-O46 -> 0
A47: =A46+1 -> 14 | K47: =_xlfn.IFNA(VLOOKUP(B47,データ!$B$3:$O$137,12,0),"") | L47: =_xlfn.IFNA(VLOOKUP(B47,データ!$B$3:$O$137,13,0),"") | M47: =_xlfn.IFNA(VLOOKUP(B47,データ!$B$3:$D$127,3,FALSE),"") | N47: =IF(L47="kg",M47*E47/1000,AND(IF(L47="PCE",E47))) -> FALSE | O47: =SUMIF(INVOICE!$B$33:$C$45,B46,INVOICE!$F$33:$F$45) -> 0 | P47: =+E48-O47 -> 0
A48: =A47+1 -> 15 | K48: =_xlfn.IFNA(VLOOKUP(B48,データ!$B$3:$O$137,12,0),"") | L48: =_xlfn.IFNA(VLOOKUP(B48,データ!$B$3:$O$137,13,0),"") | M48: =_xlfn.IFNA(VLOOKUP(B48,データ!$B$3:$D$127,3,FALSE),"") | N48: =IF(L48="kg",M48*E48/1000,AND(IF(L48="PCE",E48))) -> FALSE | O48: =SUMIF(INVOICE!$B$33:$C$45,B47,INVOICE!$F$33:$F$45) -> 0 | P48: =+E49-O48 -> 0
A49: 合計 （Total) | H49: =SUM(H34:I48) -> 23627.37
A51: 原産国 (Country of Origin) : VIETNAM | F51: 署名（ Singnature )
A52: CIF TO NAGOYA PORT

Sheet PL tong
A1: PACKING LIST
G5: =INVOICE!G5 -> インボイス作成日（Date): 5/12/2025
A8: 依頼住 (Shipper Address) | G8: =INVOICE!G8 -> Invoice No MASUDA VN-JP 019/25
A10: MASUDA VINYL VIETNAM CO.,LTD
A11: LOT NO1 DONG VANG DINH TRAM INDUSTRIAL ZONE | G11: (原産国) Country of Origin | I11: (仕向先国名) Country of Destination
A12: NENH TOWN VIET YEN DISTRICT BAC GIANG PROVINCE
A13: TEL : 0204 3662 777 | G13: VIETNAM | I13: JAPAN
A14: FAX : 0204 3662 825 | G14: 支払条件 (Terms of Payment)
G15: 20日締め翌月末支払 (Invoice will be closed on 20th every month and payment at end of the following month)
A17: 荷受人(Consigneer)
A20: MASUDA VINYL CO.,LTD | G20: 備考 (Remark):
A21: 390ROKUGAIKECYOU KITAKU
A22: NAGOYA CITY AICHI JAPAN | G22: P | H22: 有償（Commerical Value)
A23: TEL : 052-901-9373 | H23: 無償（No Commerical Value)
A24: FAX : 052-901-6943
H25: 贈物（Gift)
A26: From (発地国) | E26: Via (経由国) | H26: 商品見本（ Sample, No Commercial Value )
A27: BACGIANG VIETNAM | E27: CIF | H27: その他（Other)
A28: To (着地国)
A29: NAGOYA JAPAN
A31: ラベル内容 (Marks & Nos.) | B31: 内容品の記載 (Description) | D31: 単位 （Unit） | E31: 数量 （Quantity) | F31: 梱包 （Packing） | H31: 箱数 ( Number of Boxs) | I31: パレット数 ( Number of Pallets) | J31: 総重量 (Gross weight)
L34: trọng lượng | M34: Net weight | N34: Túi | O34: Thùng
A35: 1 | B35: ='IV tong'!B34:C34 -> PUROTEKUTA 55788-60110 | D35: ='IV tong'!D34 -> pcs | E35: ='IV tong'!E34 -> 13000 | F35: =VLOOKUP(B35,データ!$B$3:$E$85,4,FALSE) -> 500 | H35: =E35/F35 -> 26 | I35: 5 | J35: =M35+N35+O35 -> 351 | K35: pcs | L35: =VLOOKUP(B35,データ!$B$3:$D$89,3,FALSE) -> 25 | M35: =E35*L35/1000 -> 325 | O35: =H35*1 -> 26
A36: =A35+1 -> 2 | B36: ='IV tong'!B35:C35 -> PUROTEKUTA 55788-16110 | D36: ='IV tong'!D35 -> pcs | E36: ='IV tong'!E35 -> 11000 | F36: =VLOOKUP(B36,データ!$B$3:$E$85,4,FALSE) -> 500 | H36: =E36/F36 -> 22 | J36: =M36+N36+O36 -> 297 | L36: =VLOOKUP(B36,データ!$B$3:$D$89,3,FALSE) -> 25 | M36: =E36*L36/1000 -> 275 | O36: =H36*1 -> 22
A37: =A36+1 -> 3 | B37: ='IV tong'!B36:C36 -> PUROTEKUTA 55788-K0060 | D37: ='IV tong'!D36 -> pcs | E37: ='IV tong'!E36 -> 24500 | F37: =VLOOKUP(B37,データ!$B$3:$E$85,4,FALSE) -> 500 | H37: =E37/F37 -> 49 | J37: =M37+N37+O37 -> 612.5 | K37: m | L37: =VLOOKUP(B37,データ!$B$3:$D$89,3,FALSE) -> 23 | M37: =E37*L37/1000 -> 563.5 | O37: =H37*1 -> 49
A38: =A37+1 -> 4 | B38: ='IV tong'!B37:C37 -> PUROTEKUTA 2A4P1-022G | D38: ='IV tong'!D37 -> pcs | E38: ='IV tong'!E37 -> 11000 | F38: =VLOOKUP(B38,データ!$B$3:$E$85,4,FALSE) -> 500 | H38: =E38/F38 -> 22 | J38: =M38+N38+O38 -> 280.5 | K38: bag | L38: =VLOOKUP(B38,データ!$B$3:$D$89,3,FALSE) -> 23.5 | M38: =E38*L38/1000 -> 258.5 | O38: =H38*1 -> 22
A39: =A38+1 -> 5 | B39: ='IV tong'!B38:C38 -> PUROTEKUTA 55788-48090 | D39: ='IV tong'!D38 -> pcs | E39: ='IV tong'!E38 -> 9000 | F39: =VLOOKUP(B39,データ!$B$3:$E$85,4,FALSE) -> 500 | H39: =E39/F39 -> 18 | J39: =M39+N39+O39 -> 243 | L39: =VLOOKUP(B39,データ!$B$3:$D$89,3,FALSE) -> 25 | M39: =E39*L39/1000 -> 225 | O39: =H39*1 -> 18
A40: =A39+1 -> 6 | B40: ='IV tong'!B39:C39 -> PUROTEKUTA 55788-52360 | D40: ='IV tong'!D39 -> pcs | E40: ='IV tong'!E39 -> 5000 | F40: =VLOOKUP(B40,データ!$B$3:$E$85,4,FALSE) -> 500 | H40: =E40/F40 -> 10 | J40: =M40+N40+O40 -> 135 | L40: =VLOOKUP(B40,データ!$B$3:$D$89,3,FALSE) -> 25 | M40: =E40*L40/1000 -> 125 | O40: =H40*1 -> 10
A41: =A40+1 -> 7 | B41: ='IV tong'!B40:C40 -> PUROTEKUTA 55788-52350 | D41: ='IV tong'!D40 -> pcs | E41: ='IV tong'!E40 -> 6000 | F41: =VLOOKUP(B41,データ!$B$3:$E$85,4,FALSE) -> 500 | H41: =E41/F41 -> 12 | J41: =M41+N41+O41 -> 153 | L41: =VLOOKUP(B41,データ!$B$3:$D$89,3,FALSE) -> 23.5 | M41: =E41*L41/1000 -> 141 | O41: =H41*1 -> 12
A42: =A41+1 -> 8 | B42: ='IV tong'!B41:C41 -> TABLE EDGE MG23 | D42: ='IV tong'!D41 -> m | E42: ='IV tong'!E41 -> 4000 | F42: =VLOOKUP(B42,データ!$B$3:$E$85,4,FALSE) -> 50 | H42: =E42/F42 -> 80 | I42: 1 | J42: =M42+N42+O42 -> 392 | L42: =VLOOKUP(B42,データ!$B$3:$D$198,3,FALSE) -> 78 | M42: =E42*L42/1000 -> 312 | O42: =H42*1 -> 80
A43: =A42+1 -> 9 | B43: ='IV tong'!B42:C42 -> TABLE EDGE MI3 156 | D43: ='IV tong'!D42 -> pcs | E43: ='IV tong'!E42 -> 240 | F43: =VLOOKUP(B43,データ!$B$3:$E$85,4,FALSE) -> 30 | H43: =E43/F43 -> 8 | J43: =M43+N43+O43 -> 173.9312 | L43: =VLOOKUP(B43,データ!$B$3:$D$198,3,FALSE) -> 691.38 | M43: =E43*L43/1000 -> 165.9312 | O43: =H43*1 -> 8
A44: =A43+1 -> 10 | B44: ='IV tong'!B43:C43 -> MASK 42811 | D44: ='IV tong'!D43 -> bag | E44: ='IV tong'!E43 -> 12000 | F44: =VLOOKUP(B44,データ!$B$3:$E$85,4,FALSE) -> 120 | H44: =E44/F44 -> 100 | I44: 5 | J44: =M44+N44+O44 -> 1049.6 | L44: =VLOOKUP(B44,データ!$B$3:$D$198,3,FALSE) -> 83.3 | M44: =E44*L44/1000 -> 999.6 | O44: =H44*0.5 -> 50
A45: =A44+1 -> 11 | L45: =VLOOKUP(B45,データ!$B$3:$D$198,3,FALSE) -> #N/A | M45: =E45*L45/1000 -> #N/A | O45: =H45*1 -> 0
A46: =A45+1 -> 12 | L46: =VLOOKUP(B46,データ!$B$3:$D$198,3,FALSE) -> #N/A | M46: =E46*L46/1000 -> #N/A | O46: =H46*1 -> 0
A47: =A46+1 -> 13 | L47: =VLOOKUP(B47,データ!$B$3:$D$198,3,FALSE) -> #N/A | M47: =E47*L47/1000 -> #N/A | O47: =H47*1 -> 0
L48: =VLOOKUP(B48,データ!$B$3:$D$198,3,FALSE) -> #N/A | M48: =E48*L48/1000 -> #N/A | O48: =H48*1 -> 0
A49: 合計 （Total) | E49: =SUMIF(D35:D48,K35,E35:E48) -> 79740 | H49: =SUMIF(D35:D48,K35,H35:H48)+ SUMIF(D35:D48,K38,H35:H48) -> 267 | I49: =SUM(I35:I48) -> 11 | J49: =SUM(J35:J48)+220 -> 3907.5312
E51: =SUMIF(D35:D48,K37,E35:E48) -> 4000 | H51: =SUMIF(D35:D48,K37,H35:H48) -> 80
A52: CIF TO NAGOYA PORT
A53: 郵便物の個数 ( Number of pieces, m) : | D53: =E49 -> 79740 | E53: =E51 -> 4000 | H53: 署名（ Singnature )
...

Sheet Yeu cau thanh toan
J1: 45863
A2: 御請求書 HÓA ĐƠN YÊU CẦU THANH TOÁN
A9: 株式会社 MASUDA VINYL CO.,LTD 様
A10: Kính gửi :
G13: 〖振り込む先〗
A14: 毎度有り難うございます。 | G14: Thông tin chuyển khoản
A15: Xin chân thành cảm ơn quý công ty. | G15: 銀行： BANK FOR FOREIGN TRADE OF VIETNAM - BAC GIANG BRANCH
A16: 下記の通り、御請求申し上げます。 | G16: (Ngân hàng)
A17: Chúng tôi xin phép gửi yêu cầu thanh toán bên dưới. | G17: SWIFT CODE : BFTVVNVX073
G18: 口座番号: 0731370684223
G19: (Số tài khoản)
G20: MASUDA VINYL VIETNAM CO.,LTD
B22: 前回請求額 Nợ cũ | C22: 御入金額 Đã thanh toán | D22: 繰越額 Nợ tồn | E22: 御買上額 Mua hàng lần mới nhất | F22: 消費税 Tiền thuế | G22: 今回御請求額 Tổng số tiền lần này | H22: 相殺金額 Đối trừ công nợ | I22: 差引き請求額 Số tiền yêu cẩu thanh toán
B23: 0 | C23: 0 | D23: =B23-C23 -> 0 | E23: =I53 -> 20818.6 | F23: =E23*0 -> 0 | G23: =E23+F23+D23 -> 20818.6 | H23: =J63 -> 0 | I23: =G23-H23 -> 20818.6
A25: 請 求 明 細
A26: Chi tiết thanh toán
A28: 伝票No Số phiếu | C28: ベトナム出荷日 Ngày xuất phía VN | D28: 商品名/規格 Tên hàng / Quy cách | F28: 数量 Số lượng | G28: 単位 Đơn vị | H28: 単価 Đơn giá | I28: 金額 Số tiền | J28: 摘要 Chú thích
A29: MASUDA | C29: 45878 | D29: TABLE EDGE MG23 | F29: 4000 | G29: pcs | H29: =VLOOKUP(D29,データ!B3:E87,2,FALSE) -> 0.61 | I29: =H29*F29 -> 2440 | J29: =F29/50 -> 80 | L29: 品名 | M29: 単価 | N29: 単位 | O29: 出荷数 | P29: 梱包
A30: VN-JP 013 | L30: MASUGOMU 4140 | M30: 0.71 | N30: pcs | O30: =VLOOKUP(L30,[1]原紙!$D$29:$F$62,3,FALSE) -> #N/A | P30: =O30/180 -> #N/A
A31: MASUDA | C31: =C29 -> 45878 | D31: PUROTEKUTA 2A4P1-022G | F31: 10000 | G31: pcs | H31: =VLOOKUP(D31,データ!B5:E89,2,FALSE) -> 0.235 | I31: =H31*F31 -> 2350 | J31: =F31/500 -> 20 | L31: MASUGOMU 4080 | M31: 0.4 | N31: pcs | O31: =VLOOKUP(L31,[2]原紙!$D$29:$F$62,3,FALSE) -> #N/A | P31: =O31/350 -> #N/A
A32: =A30 -> VN-JP 013 | L32: TABLE EDGE MG23 | M32: 0.5 | N32: m | O32: =VLOOKUP(L32,[2]原紙!$D$29:$F$62,3,FALSE) -> #N/A | P32: =O32/50 -> #N/A
A33: MASUDA | C33: =C29 -> 45878 | D33: PUROTEKUTA 55788-48090 | F33: 9000 | G33: pcs | H33: =VLOOKUP(D33,データ!B9:E93,2,FALSE) -> 0.251 | I33: =H33*F33 -> 2259 | J33: =F33/500 -> 18
A34: =A30 -> VN-JP 013
A35: MASUDA | C35: =C29 -> 45878 | D35: PUROTEKUTA 55788-60110 | F35: 11000 | G35: pcs | H35: =VLOOKUP(D35,データ!B11:E95,2,FALSE) -> 0.223 | I35: =H35*F35 -> 2453 | J35: =F35/500 -> 22 | L35: SHEET JOINT 100L (5226-1000) | M35: 0.037 | N35: pcs | O35: =VLOOKUP(L35,[1]原紙!$D$29:$F$62,3,FALSE) -> #N/A | P35: =O35/3000 -> #N/A
A36: =A30 -> VN-JP 013 | L36: SHEET JOINT 150L | M36: 0.05 | N36: pcs | O36: =VLOOKUP(L36,[1]原紙!$D$29:$F$62,3,FALSE) -> #N/A | P36: =O36/1500 -> #N/A
A37: MASUDA | C37: =C29 -> 45878 | D37: PUROTEKUTA 55788-16110 | F37: 11000 | G37: pcs | H37: =VLOOKUP(D37,データ!B13:E97,2,FALSE) -> 0.223 | I37: =H37*F37 -> 2453 | J37: =F37/500 -> 22 | L37: SHEET JOINT 200L | M37: 0.07 | N37: pcs | O37: =VLOOKUP(L37,[1]原紙!$D$29:$F$62,3,FALSE) -> #N/A | P37: =O37/1500 -> #N/A
A38: =A30 -> VN-JP 013 | L38: SHEET JOINT 290L | M38: 0.08 | N38: pcs | O38: =VLOOKUP(L38,[1]原紙!$D$29:$F$62,3,FALSE) -> #N/A | P38: =O38/1000 -> #N/A
A39: MASUDA | C39: =C31 -> 45878 | D39: PUROTEKUTA 55788-K0060 | F39: 25000 | G39: pcs | H39: =VLOOKUP(D39,データ!B15:E107,2,FALSE) -> 0.224 | I39: =H39*F39 -> 5600 | J39: =F39/500 -> 50 | L39: TABLE EDGE MI3 | M39: 0.587 | N39: m | O39: =VLOOKUP(L39,[1]原紙!$D$29:$F$62,3,FALSE) -> #N/A | P39: =O39/50 -> #N/A
A40: =A32 -> VN-JP 013 | L40: TABLE EDGE MI3 156 | M40: 2.875 | N40: pcs | O40: =VLOOKUP(L40,[1]原紙!$D$29:$F$62,3,FALSE) -> 205 | P40: =O40/30 -> 6.8333333
A41: MASUDA | C41: =C33 -> 45878 | D41: PUROTEKUTA 55788-52350 | F41: 4000 | G41: pcs | H41: =VLOOKUP(D41,データ!B19:E112,2,FALSE) -> 0.213 | I41: =H41*F41 -> 852 | J41: =F41/500 -> 8
A42: =A34 -> VN-JP 013
A43: MASUDA | C43: =C35 -> 45878 | D43: PUROTEKUTA 55788-52360 | F43: 4000 | G43: pcs | H43: =VLOOKUP(D43,データ!B21:E114,2,FALSE) -> 0.223 | I43: =H43*F43 -> 892 | J43: =F43/500 -> 8
A44: =A36 -> VN-JP 013
A45: MASUDA | C45: =C39 -> 45878 | D45: DIP TUBE | F45: 680 | G45: pcs | H45: =VLOOKUP(D45,データ!B25:E118,2,FALSE) -> 1.22 | I45: =H45*F45 -> 829.6 | J45: =F45/100 -> 6.8
A46: =A40 -> VN-JP 013
A47: MASUDA | C47: =C41 -> 45878 | D47: TABLE EDGE MI3 156 | F47: 240 | G47: pcs | H47: =VLOOKUP(D47,データ!B27:E120,2,FALSE) -> 2.875 | I47: =H47*F47 -> 690 | J47: =F47/30 -> 8
A48: =A42 -> VN-JP 013
H51: 合計 Tổng | I51: =SUM(I29:I50) -> 20818.6 | L51: MASUGOMU 4120 | M51: 1.22 | N51: pcs | O51: =VLOOKUP(L51,[1]原紙!$D$29:$F$62,3,FALSE) -> 10080 | P51: =O51/360 -> 28
H52: 消費税 Thuế VAT | I52: =I51*0 -> 0 | L52: MASUGOMU 4130 | M52: 1.22 | N52: pcs | O52: =VLOOKUP(L52,[1]原紙!$D$29:$F$62,3,FALSE) -> 10260 | P52: =O52/540 -> 19
H53: 税込合計 Tổng cả thuế | I53: =I51+I52 -> 20818.6 | L53: MASUGOMU 4240 | M53: 0.34 | N53: pcs | O53: =VLOOKUP(L53,[1]原紙!$D$29:$F$62,3,FALSE) -> 22320 | P53: =O53/360 -> 62
...

Sheet HS code
A3: TÊN SP | C3: MÃ HS
A4: MASUGOMU 4140 | C4: 39161020
A5: MASUGOMU 4080 | C5: 39161020
A6: TABLE EDGE MG23 | C6: 39169099
A7: KATEKUSU 3ø 100L | C7: 39169099
A8: KATEKUSU 3ø 150L | C8: 39169099
A9: KATEKUSU 4ø 100L | C9: 39169099
A10: KATEKUSU 5ø 183L | C10: 39169099
A11: SHEET JOINT | C11: 39269049
A12: TABLE EDGE MI3 | C12: 39169099
A13: TABLE EDGE MI3 156 | C13: 39169099
A14: TABLE EDGE MI3 26 | C14: 39169099
A15: PUROTEKUTA 1350L | C15: 39169099
... A18: DIP TUBE | C18: 39173290
C105: =SUM(C74:C104) -> 0

Sheet データ
A2: No | B2: 品名 | C2: 単価 | D2: 重さ | E2: 梱包 | F2: 出荷数 | G2: 箱数 | H2: 使用材 | I2: 袋 | J2: 段ボール | K2: 総数量 | L2: 単位 | M2: Mã HS code | N2: SL2
A3: 1 | B3: MASUGOMU 4140 | C3: 0.78 | D3: 100 | E3: 180 | F3: =_xlfn.IFNA(VLOOKUP(B3,'PACKING LIST'!$B$35:$F$54,5,FALSE),0) -> 0 | G3: =ROUNDUP(F3/E3,0) -> 0 | H3: =F3*D3/1000 -> 0 | I3: =G3*6*0.4/1000 -> 0 | J3: =G3*0.7 -> 0 | K3: =J3+I3+H3 -> 0 | L3: pcs | M3: 39161020 | N3: Kg
A4: =A3+1 -> 2 | B4: MASUGOMU 4080 | C4: =0.44 -> 0.44 | D4: 53 | E4: 350 | F4: =_xlfn.IFNA(VLOOKUP(B4,'PACKING LIST'!$B$35:$F$54,5,FALSE),0) -> 0 | G4: =ROUNDUP(F4/E4,0) -> 0 | H4: =F4*D4/1000 -> 0 | I4: =G4*7*0.4/1000 -> 0 | J4: =G4*0.7 -> 0 | K4: =J4+I4+H4 -> 0 | L4: pcs | M4: 39161020 | N4: Kg
A5: 3 | B5: MASUGOMU 4090 | C5: 0.49 | D5: 60 | E5: 360 | F5: =_xlfn.IFNA(VLOOKUP(B5,'PACKING LIST'!$B$35:$F$54,5,FALSE),0) -> 0 | G5: =ROUNDUP(F5/E5,0) -> 0 | H5: =F5*D5/1000 -> 0 | I5: =G5*7*0.4/1000 -> 0 | J5: =G5*0.7 -> 0 | K5: =J5+I5+H5 -> 0 | L5: pcs | M5: 39161020 | N5: Kg
A6: =A5+1 -> 4 | B6: MASUGOMU 4120 | C6: =0.38 -> 0.38 | D6: 43 | E6: 360 | F6: =_xlfn.IFNA(VLOOKUP(B6,'PACKING LIST'!$B$35:$F$54,5,FALSE),0) -> 0 | G6: =ROUNDUP(F6/E6,0) -> 0 | H6: =F6*D6/1000 -> 0 | I6: =G6*7*0.4/1000 -> 0 | J6: =G6*0.7 -> 0 | K6: =J6+I6+H6 -> 0 | L6: pcs | M6: 39161020 | N6: Kg
A7: =A6+1 -> 5 | B7: MASUGOMU 4130 | C7: =0.25 -> 0.25 | D7: 28 | E7: 540 | F7: =_xlfn.IFNA(VLOOKUP(B7,'PACKING LIST'!$B$35:$F$54,5,FALSE),0) -> 0 | G7: =ROUNDUP(F7/E7,0) -> 0 | H7: =F7*D7/1000 -> 0 | I7: =G7*7*0.4/1000 -> 0 | J7: =G7*0.7 -> 0 | K7: =J7+I7+H7 -> 0 | L7: pcs | M7: 39161020 | N7: Kg
A8: =A7+1 -> 6 | B8: MASUGOMU 4240 | C8: =0.38 -> 0.38 | D8: 43 | E8: 360 | F8: =_xlfn.IFNA(VLOOKUP(B8,'PACKING LIST'!$B$35:$F$54,5,FALSE),0) -> 0 | G8: =ROUNDUP(F8/E8,0) -> 0 | H8: =F8*D8/1000 -> 0 | I8: =G8*7*0.4/1000 -> 0 | J8: =G8*0.7 -> 0 | K8: =J8+I8+H8 -> 0 | L8: pcs | M8: 39161020 | N8: Kg
A9: =A8+1 -> 7 | B9: TABLE EDGE MG23 | C9: 0.61 | D9: =3.9/50*1000 -> 78 | E9: 50 | F9: =_xlfn.IFNA(VLOOKUP(B9,'PACKING LIST'!$B$35:$F$54,5,FALSE),0) -> 4000 | G9: =ROUNDUP(F9/E9,0) -> 80 | H9: =G9*D9 -> 6240 | J9: =G9*0 -> 0 | K9: =J9+I9+H9 -> 6240 | L9: m | M9: 39169092 | N9: Kg
A10: =A9+1 -> 8 | B10: KATEKUSU 2.5ø 73L | C10: 0.011 | D10: 0.7 | E10: 20000 | F10: =_xlfn.IFNA(VLOOKUP(B10,'PACKING LIST'!$B$35:$F$54,5,FALSE),0) -> 0 | G10: =ROUNDUP(F10/E10,0) -> 0 | H10: =F10*D10/1000 -> 0 | J10: =G10*0.7 -> 0 | K10: =J10+I10+H10 -> 0 | L10: pcs | M10: 39169092 | N10: Kg
A11: =A10+1 -> 9 | B11: KATEKUSU 2.5ø 50L | C11: 0.01 | D11: 0.7 | E11: 20000 | F11: =_xlfn.IFNA(VLOOKUP(B11,'PACKING LIST'!$B$35:$F$54,5,FALSE),0) -> 0 | G11: =ROUNDUP(F11/E11,0) -> 0 | H11: =F11*D11/1000 -> 0 | J11: =G11*0.7 -> 0 | K11: =J11+I11+H11 -> 0 | L11: pcs | M11: 39169092 | N11: Kg
A12: =A10+1 -> 9 | B12: KATEKUSU 2.5ø 95L | C12: 0.013 | D12: 0.7 | E12: 20000 | F12: =_xlfn.IFNA(VLOOKUP(B12,'PACKING LIST'!$B$35:$F$54,5,FALSE),0) -> 0 | G12: =ROUNDUP(F12/E12,0) -> 0 | H12: =F12*D12/1000 -> 0 | J12: =G12*0.7 -> 0 | K12: =J12+I12+H12 -> 0 | L12: pcs | M12: 39169092 | N12: Kg
A13: =A10+1 -> 9 | B13: KATEKUSU 2.5ø 100L | C13: 0.013 | D13: 0.8 | E13: 20000 | F13: =_xlfn.IFNA(VLOOKUP(B13,'PACKING LIST'!$B$35:$F$54,5,FALSE),0) -> 0 | G13: =ROUNDUP(F13/E13,0) -> 0 | H13: =F13*D13/1000 -> 0 | J13: =G13*0.7 -> 0 | K13: =J13+I13+H13 -> 0 | L13: pcs | M13: 39169092 | N13: Kg
A14: =A12+1 -> 10 | B14: KATEKUSU 2.5ø 135L | C14: 0.015 | D14: 0.8 | E14: 20000 | F14: =_xlfn.IFNA(VLOOKUP(B14,'PACKING LIST'!$B$35:$F$54,5,FALSE),0) -> 0 | G14: =ROUNDUP(F14/E14,0) -> 0 | H14: =F14*D14/1000 -> 0 | J14: =G14*0.7 -> 0 | K14: =J14+I14+H14 -> 0 | L14: pcs | M14: 39169092 | N14: Kg
B15: KATEKUSU 3ø 30L | C15: 0.01 | D15: 0.8 | E15: 20000 | F15: =_xlfn.IFNA(VLOOKUP(B15,'PACKING LIST'!$B$35:$F$54,5,FALSE),0) -> 0 | G15: =ROUNDUP(F15/E15,0) -> 0 | H15: =F15*D15/1000 -> 0 | J15: =G15*0.7 -> 0 | K15: =J15+I15+H15 -> 0 | L15: pcs | M15: 39169092 | N15: Kg
B16: KATEKUSU 3ø 40L | C16: 0.01 | D16: 0.8 | E16: 20000 | F16: =_xlfn.IFNA(VLOOKUP(B16,'PACKING LIST'!$B$35:$F$54,5,FALSE),0) -> 0 | G16: =ROUNDUP(F16/E16,0) -> 0 | H16: =F16*D16/1000 -> 0 | J16: =G16*0.7 -> 0 | K16: =J16+I16+H16 -> 0 | L16: pcs | M16: 39169092 | N16: Kg
B17: KATEKUSU 3ø 45L | C17: 0.01 | D17: 0.8 | E17: 20000 | F17: =_xlfn.IFNA(VLOOKUP(B17,'PACKING LIST'!$B$35:$F$54,5,FALSE),0) -> 0 | G17: =ROUNDUP(F17/E17,0) -> 0 | H17: =F17*D17/1000 -> 0 | J17: =G17*0.7 -> 0 | K17: =J17+I17+H17 -> 0 | L17: pcs | M17: 39169092 | N17: Kg
B18: KATEKUSU 3ø 90L | C18: 0.013 | D18: 0.8 | E18: 20000 | F18: =_xlfn.IFNA(VLOOKUP(B18,'PACKING LIST'!$B$35:$F$54,5,FALSE),0) -> 0 | G18: =ROUNDUP(F18/E18,0) -> 0 | H18: =F18*D18/1000 -> 0 | J18: =G18*0.7 -> 0 | K18: =J18+I18+H18 -> 0 | L18: pcs | M18: 39169092 | N18: Kg
A19: =A13+1 -> 10 | B19: KATEKUSU 3ø 100L | C19: 0.013 | D19: 0.8 | E19: 20000 | F19: =_xlfn.IFNA(VLOOKUP(B19,'PACKING LIST'!$B$35:$F$54,5,FALSE),0) -> 0 | G19: =ROUNDUP(F19/E19,0) -> 0 | H19: =F19*D19/1000 -> 0 | J19: =G19*0.7 -> 0 | K19: =J19+I19+H19 -> 0 | L19: pcs | M19: 39169092 | N19: Kg
A20: =A19+1 -> 11 | B20: KATEKUSU 3ø 150L | C20: 0.013 | D20: 1.1 | E20: 10000 | F20: =_xlfn.IFNA(VLOOKUP(B20,'PACKING LIST'!$B$35:$F$54,5,FALSE),0) -> 0 | G20: =ROUNDUP(F20/E20,0) -> 0 | H20: =F20*D20/1000 -> 0 | J20: =G20*0.7 -> 0 | K20: =J20+I20+H20 -> 0 | L20: pcs | M20: 39169092 | N20: Kg
A21: =A19+1 -> 11 | B21: KATEKUSU 4ø 50L | C21: 0.013 | D21: 1.1 | E21: 10000 | F21: =_xlfn.IFNA(VLOOKUP(B21,'PACKING LIST'!$B$35:$F$54,5,FALSE),0) -> 0 | G21: =ROUNDUP(F21/E21,0) -> 0 | H21: =F21*D21/1000 -> 0 | J21: =G21*0.7 -> 0 | K21: =J21+I21+H21 -> 0 | L21: pcs | M21: 39169092 | N21: Kg
A22: =A20+1 -> 12 | B22: KATEKUSU 4ø 100L | C22: 0.016 | D22: 1.1 | E22: 10000 | F22: =_xlfn.IFNA(VLOOKUP(B22,'PACKING LIST'!$B$35:$F$54,5,FALSE),0) -> 0 | G22: =ROUNDUP(F22/E22,0) -> 0 | H22: =F22*D22/1000 -> 0 | J22: =G22*0.7 -> 0 | K22: =J22+I22+H22 -> 0 | L22: pcs | M22: 39169092 | N22: Kg
A23: =A22+1 -> 13 | B23: KATEKUSU 5ø 183L | C23: 0.053 | D23: 3.7 | E23: 5000 | F23: =_xlfn.IFNA(VLOOKUP(B23,'PACKING LIST'!$B$35:$F$54,5,FALSE),0) -> 0 | G23: =ROUNDUP(F23/E23,0) -> 0 | H23: =F23*D23/1000 -> 0 | J23: =G23*0.7 -> 0 | K23: =J23+I23+H23 -> 0 | L23: pcs | M23: 39169092 | N23: Kg
A24: =A23+1 -> 14 | B24: SHEET JOINT 100L | C24: 0.037 | D24: 4.3 | E24: 3000 | F24: =_xlfn.IFNA(VLOOKUP(B24,'PACKING LIST'!$B$35:$F$54,5,FALSE),0) -> 0 | G24: =ROUNDUP(F24/E24,0) -> 0 | H24: =F24*D24/1000 -> 0 | J24: =G24*0.7 -> 0 | K24: =J24+I24+H24 -> 0 | L24: pcs | M24: 39269049 | N24: PCE
A25: =A24+1 -> 15 | B25: SHEET JOINT 150L | C25: 0.05 | D25: 5.5 | E25: 1500 | F25: =_xlfn.IFNA(VLOOKUP(B25,'PACKING LIST'!$B$35:$F$54,5,FALSE),0) -> 0 | G25: =ROUNDUP(F25/E25,0) -> 0 | H25: =F25*D25/1000 -> 0 | J25: =G25*0.7 -> 0 | K25: =J25+I25+H25 -> 0 | L25: pcs | M25: 39269049 | N25: PCE
A26: =A25+1 -> 16 | B26: SHEET JOINT 200L | C26: 0.07 | D26: 7.2 | E26: 1500 | F26: =_xlfn.IFNA(VLOOKUP(B26,'PACKING LIST'!$B$35:$F$54,5,FALSE),0) -> 0 | G26: =ROUNDUP(F26/E26,0) -> 0 | H26: =F26*D26/1000 -> 0 | J26: =G26*0.7 -> 0 | K26: =J26+I26+H26 -> 0 | L26: pcs | M26: 39269049 | N26: PCE
A27: =A26+1 -> 17 | B27: SHEET JOINT 290L | C27: 0.08 | D27: 12.4 | E27: 1000 | F27: =_xlfn.IFNA(VLOOKUP(B27,'PACKING LIST'!$B$35:$F$54,5,FALSE),0) -> 0 | G27: =ROUNDUP(F27/E27,0) -> 0 | H27: =F27*D27/1000 -> 0 | J27: =G27*0.7 -> 0 | K27: =J27+I27+H27 -> 0 | L27: pcs | M27: 39269049 | N27: PCE
A28: =A27+1 -> 18 | B28: TABLE EDGE MI3 | C28: 0.587 | D28: 8.4 | E28: 50 | F28: =_xlfn.IFNA(VLOOKUP(B28,'PACKING LIST'!$B$35:$F$54,5,FALSE),0) -> 0 | G28: =ROUNDUP(F28/E28,0) -> 0 | H28: =F28*D28 -> 0 | J28: =G28*0 -> 0 | K28: =J28+I28+H28 -> 0 | L28: m | M28: 39169092 | N28: Kg
A29: =A28+1 -> 19 | B29: TABLE EDGE MI3 156 | C29: 2.875 | D29: =4140*167/1000 -> 691.38 | E29: 30 | F29: =_xlfn.IFNA(VLOOKUP(B29,'PACKING LIST'!$B$35:$F$54,5,FALSE),0) -> 240 | G29: =ROUNDUP(F29/E29,0) -> 8 | H29: =F29*D29 -> 165931.2 | J29: =G29*1 -> 8 | K29: =J29+I29+H29 -> 165939.2 | L29: pcs | M29: 39169092 | N29: Kg
A30: =A29+1 -> 20 | B30: TABLE EDGE MI3 26 | C30: 3.017 | D30: =4416*167/1000 -> 737.472 | E30: 30 | F30: =_xlfn.IFNA(VLOOKUP(B30,'PACKING LIST'!$B$35:$F$54,5,FALSE),0) -> 0 | G30: =ROUNDUP(F30/E30,0) -> 0 | H30: =F30*D30 -> 0 | J30: =G30*1 -> 0 | K30: =J30+I30+H30 -> 0 | L30: pcs | M30: 39169092 | N30: Kg
A31: =A30+1 -> 21 | B31: TABLE EDGE MI3 256 | C31: 3.229 | D31: =0.77*1000 -> 770 | E31: 30 | F31: =_xlfn.IFNA(VLOOKUP(B31,'PACKING LIST'!$B$35:$F$54,5,FALSE),0) -> 0 | G31: =ROUNDUP(F31/E31,0) -> 0 | H31: =F31*D31 -> 0 | J31: =G31*1 -> 0 | K31: =J31+I31+H31 -> 0 | L31: pcs | M31: 39169092 | N31: Kg
A32: =A31+1 -> 22 | B32: TABLE EDGE MI3 36 | C32: 3.158 | D32: =0.84*1000 -> 840 | E32: 30 | F32: =_xlfn.IFNA(VLOOKUP(B32,'PACKING LIST'!$B$35:$F$54,5,FALSE),0) -> 0 | G32: =ROUNDUP(F32/E32,0) -> 0 | H32: =F32*D32 -> 0 | J32: =G32*1 -> 0 | K32: =J32+I32+H32 -> 0 | L32: pcs | M32: 39169092 | N32: Kg
A33: =A32+1 -> 23 | B33: TABLE EDGE MI3 155 | C33: 2.509 | D33: =0.624*1000 -> 624 | E33: 30 | F33: =_xlfn.IFNA(VLOOKUP(B33,'PACKING LIST'!$B$35:$F$54,5,FALSE),0) -> 0 | G33: =ROUNDUP(F33/E33,0) -> 0 | H33: =F33*D33 -> 0 | J33: =G33*1 -> 0 | K33: =J33+I33+H33 -> 0 | L33: pcs | M33: 39169092 | N33: Kg
A34: =A33+1 -> 24 | B34: TABLE EDGE MI3 25 | C34: 2.698 | D34: =0.673*1000 -> 673 | E34: 30 | F34: =_xlfn.IFNA(VLOOKUP(B34,'PACKING LIST'!$B$35:$F$54,5,FALSE),0) -> 0 | G34: =ROUNDUP(F34/E34,0) -> 0 | H34: =F34*D34 -> 0 | J34: =G34*1 -> 0 | K34: =J34+I34+H34 -> 0 | L34: pcs | M34: 39169092 | N34: Kg
A35: =A34+1 -> 25 | B35: PUROTEKUTA 55788-02270 | C35: 0.2046 | D35: 21.6 | E35: 500 | F35: =_xlfn.IFNA(VLOOKUP(B35,'PACKING LIST'!$B$35:$F$54,5,FALSE),0) -> 0 | G35: =ROUNDUP(F35/E35,0) -> 0 | H35: =F35*D35/1000 -> 0 | J35: =G35*1 -> 0 | K35: =J35+I35+H35 -> 0 | L35: pcs | M35: 39169092 | N35: Kg
A36: =A35+1 -> 26 | B36: PUROTEKUTA 1422L (55788-42050) | C36: 0.234 | D36: 24 | E36: 500 | F36: =_xlfn.IFNA(VLOOKUP(B36,'PACKING LIST'!$B$35:$F$54,5,FALSE),0) -> 0 | G36: =ROUNDUP(F36/E36,0) -> 0 | H36: =F36*D36/1000 -> 0 | J36: =G36*1 -> 0 | K36: =J36+I36+H36 -> 0 | L36: pcs | M36: 39169092 | N36: Kg | P36: =263636+165000 -> 428636
B37: PUROTEKUTA 55788-TOA0010 | C37: 0.224 | D37: 24 | E37: 500 | F37: =_xlfn.IFNA(VLOOKUP(B37,'PACKING LIST'!$B$35:$F$54,5,FALSE),0) -> 0 | G37: =ROUNDUP(F37/E37,0) -> 0 | H37: =F37*D37/1000 -> 0 | J37: =G37*1 -> 0 | K37: =J37+I37+H37 -> 0 | L37: pcs | M37: 39169092 | N37: Kg
B38: PUROTEKUTA 55788-TOA020 | C38: 0.224 | D38: 24 | E38: 500 | F38: =_xlfn.IFNA(VLOOKUP(B38,'PACKING LIST'!$B$35:$F$54,5,FALSE),0) -> 0 | G38: =ROUNDUP(F38/E38,0) -> 0 | H38: =F38*D38/1000 -> 0 | J38: =G38*1 -> 0 | K38: =J38+I38+H38 -> 0 | L38: pcs | M38: 39169092 | N38: Kg
A39: =A36+1 -> 27 | B39: PUROTEKUTA 1383L OK100 | C39: 0.228 | D39: 21.7 | E39: 500 | F39: =_xlfn.IFNA(VLOOKUP(B39,'PACKING LIST'!$B$35:$F$54,5,FALSE),0) -> 0 | G39: =ROUNDUP(F39/E39,0) -> 0 | H39: =F39*D39/1000 -> 0 | J39: =G39*1 -> 0 | K39: =J39+I39+H39 -> 0 | L39: pcs | M39: 39169092 | N39: Kg
A40: =A39+1 -> 28 | B40: PUROTEKUTA 2A4P1-018G | C40: 0.229 | D40: 22.1 | E40: 500 | F40: =_xlfn.IFNA(VLOOKUP(B40,'PACKING LIST'!$B$35:$F$54,5,FALSE),0) -> 0 | G40: =ROUNDUP(F40/E40,0) -> 0 | H40: =F40*D40/1000 -> 0 | J40: =G40*1 -> 0 | K40: =J40+I40+H40 -> 0 | L40: pcs | M40: 39169092 | N40: Kg
A41: =A40+1 -> 29 | B41: PUROTEKUTA 55788-48080 | C41: 0.251 | D41: 25 | E41: 500 | F41: =_xlfn.IFNA(VLOOKUP(B41,'PACKING LIST'!$B$35:$F$54,5,FALSE),0) -> 0 | G41: =ROUNDUP(F41/E41,0) -> 0 | H41: =F41*D41/1000 -> 0 | J41: =G41*1 -> 0 | K41: =J41+I41+H41 -> 0 | L41: pcs | M41: 39169092 | N41: Kg
...

Sheet dia chỉ
A2: FROM: MASUDA VINYL VIETNAM CO.,LTD
A4: LOT NO1 DONG VANG DINH TRAM INDUSTRIAL ZONE
A5: NENH WARD BAC NINH PROVINCE VIET NAM
A6: TEL : 0204 3662 777
A9: TO: MASUDA VINYL CO.,LTD
A11: 390ROKUGAIKECYOU KITAKU NAGOYA CITY AICHI JAPAN
A13: TEL : 052-901-9373
